Workbook

Sheet Read Me
B2: Frontier AI Coding Agent — Infrastructure Cost Model
B3: Bottom-up serving-cost model, engineered on the latest documented frontier MoE (DeepSeek-V4-Pro: 1.6T total / 49B active, hybrid sparse attention) on NVIDIA B300 (Blackwell Ultra).
B6: WHAT THIS IS
B7: A bottom-up model of what it costs to SERVE a frontier coding agent, with the infrastructure cost broken into the five
B8: requested buckets: GPU, CPU, DRAM, electricity, and human. It builds the cost of owning and running one inference
B9: node, converts that to a cost per token using measured throughput, then rolls up to cost per coding task, per developer,
B10: and compares the result to the market API price to reveal the implied gross margin.
B12: ENGINEERING BASIS (updated to the latest tech, June 2026)
B13: Grounded in DeepSeek-V4-Pro, the best-documented top-tier model (open weights + full technical report, released Apr 2026):
B14: 1.6T total parameters, 49B active per token, native FP4 experts, and Multi-Token Prediction for speculative decoding.
B15: Its headline change is a hybrid sparse-attention stack (Compressed Sparse Attention + Heavily Compressed Attention, plus
B16: Manifold-Constrained Hyper-Connections in place of the residual stream). Versus the prior DeepSeek-V3.2, V4 cuts per-token
... B48: Prepared June 2026. All external data points are dated on the Sources tab.

Sheet Inputs
A1: INPUTS & ASSUMPTIONS
A2: Edit BLUE cells. Yellow = highest-leverage assumptions. All other tabs recalculate from here.
A3: Assumption | B3: Value | C3: Unit | D3: Source / note
A4: HARDWARE — GPU
A5: GPU model | B5: NVIDIA B300 | D5: Blackwell Ultra; the volume-production inference GPU in 2026
A6: GPU unit cost | B6: 48000 | C6: $/GPU | D6: B300 list ~$40k-$50k; DGX B300 8-GPU ~$300k (Spheron; Tech-Insider 2026)
A7: GPUs per node | B7: 8 | C7: GPUs | D7: HGX/DGX B300 8-GPU baseboard
A8: GPU TDP | B8: 1400 | C8: W | D8: NVIDIA B300 1,400W; liquid-cooled (Spheron; VRLA 2026)
A9: GPU economic life | B9: 3 | C9: years | D9: Assumption; 3-5y typical for leading-edge AI GPUs
A10: HBM per GPU | B10: 288 | C10: GB | D10: 288GB HBM3e (incl. in GPU price, not the DRAM bucket)
A11: HARDWARE — CPU (host)
A12: Host CPUs per node | B12: 2 | C12: CPUs | D12: Dual-socket host (e.g. Xeon 6776P in DGX B300)
A13: CPU unit cost | B13: 12500 | C13: $/CPU | D13: High-core server CPU, estimate
A14: CPU TDP | B14: 350 | C14: W | D14: Top-bin server CPU, estimate
A15: Non-GPU hardware life | B15: 5 | C15: years | D15: CPU / DRAM / networking / chassis
A16: HARDWARE — DRAM (host system memory)
A17: System DRAM per node | B17: 3072 | C17: GB | D17: ~3 TB/node; sized for V4 CPU-extended KV cache (HiSparse) at long context
A18: DRAM price | B18: 14 | C18: $/GB | D18: Server DDR5 RDIMM ~$14/GB; 64GB RDIMM crossed $900 in Q1'26 (rampricesusa; PCSP 2026)
A19: DRAM power per node | B19: 600 | C19: W | D19: Estimate (3 TB RDIMM)
A20: HARDWARE — Other (networking, storage, chassis)
A21: Other hardware / node | B21: 80000 | C21: $/node | D21: NVSwitch/NVLink5, ConnectX/IB NICs, NVMe, chassis, PSUs (est.)
A22: Other hardware power / node | B22: 1500 | C22: W | D22: NVSwitch + NICs + fans + storage, estimate
A23: POWER
A24: Electricity price | B24: 0.08 | C24: $/kWh | D24: US industrial avg ~$0.073; hyperscale <$0.05 (EIA / Network Installers 2026)
A25: PUE | B25: 1.2 | C25: x | D25: Modern liquid-cooled AI DC 1.1-1.2 (B300 requires liquid cooling)
A26: FINANCING
A27: Cost of capital (discount rate) | B27: 0.12 | C27: % | D27: For capital-recovery factor; set 0% for straight-line depreciation
A28: MODEL ENGINEERING — frontier MoE (DeepSeek-V4-Pro)
A29: Total parameters | B29: 1600 | C29: B | D29: DeepSeek-V4-Pro 1.6T (HF model card; NVIDIA; LMSYS, Apr 2026)
A30: Active parameters / token | B30: 49 | C30: B | D30: DeepSeek-V4-Pro 49B active; closed frontier models likely higher
A31: Weight precision | B31: 0.5 | C31: bytes/param | D31: Native FP4 experts on Blackwell (FP8 = 1.0)
A32: KV-cache vs DeepSeek-V3.2 | B32: 0.1 | C32: x | D32: V4 hybrid attention (CSA+HCA): ~90% KV-cache reduction at 1M ctx
A33: Per-token FLOPs vs V3.2 | B33: 0.27 | C33: x | D33: V4: ~73% fewer per-token inference FLOPs at 1M ctx
A34: MTP speculative-decode speedup | B34: 1 | C34: x | D34: Available in V4; set 1.0 (already reflected in throughput anchor)
A35: INFERENCE THROUGHPUT — measured anchor (GB300 Blackwell Ultra)
A36: Reference GPU | B36: NVIDIA GB300 | D36: Anchor hardware (Blackwell Ultra, FP4)
A37: Ref decode (output) / 8-GPU node | B37: 46700 | C37: tok/s | D37: 5,842 tok/s/GPU x8; MLPerf v5.1 GB300 NVL72, DeepSeek-R1 FP4 offline
A38: Ref prefill (input) / 8-GPU node | B38: 116800 | C38: tok/s | D38: ~2.5x decode (prefill compute-bound); ratio per vLLM GB300 measurement
A39: Hardware multiplier | B39: 1 | C39: x | D39: Anchor is already measured on B300/GB300, so no scaling (=1.0)
A40: Serving-efficiency derate | B40: 0.7 | C40: % | D40: Interactive latency SLAs vs throughput-optimised (offline) benchmark peak
...

Sheet Node Economics
A1: NODE ECONOMICS — one 8-GPU B300 node: capex → $ / node-hour
A2: Cost to OWN and RUN one node for one hour, by component. Green = pulled from Inputs.
A3: Constants
A4: Hours per year | B4: 8760 | C4: hr
A6: Capital-recovery factors
A7: Discount rate (r) | B7: =Inputs!B27 -> 0.12
A8: GPU life (n, yrs) | B8: =Inputs!B9 -> 3
A9: Non-GPU life (n, yrs) | B9: =Inputs!B15 -> 5
A10: CRF — GPU | B10: =IF($B$7=0,1/B8,$B$7*(1+$B$7)^B8/((1+$B$7)^B8-1)) -> 0.41634898 | C10: annuity factor
A11: CRF — non-GPU | B11: =IF($B$7=0,1/B9,$B$7*(1+$B$7)^B9/((1+$B$7)^B9-1)) -> 0.27740973 | C11: annuity factor
A13: Per-node capital cost
A14: Component | B14: Capex ($/node) | C14: CRF | D14: Annualised ($/yr) | E14: $ / node-hour
A15: GPU | B15: =Inputs!B6*Inputs!B7 -> 384000 | C15: =$B$10 -> 0.41634898 | D15: =B15*C15 -> 159878.01 | E15: =D15/$B$4 -> 18.250914
A16: CPU | B16: =Inputs!B12*Inputs!B13 -> 25000 | C16: =$B$11 -> 0.27740973 | D16: =B16*C16 -> 6935.2433 | E16: =D16/$B$4 -> 0.79169444
A17: DRAM (system) | B17: =Inputs!B17*Inputs!B18 -> 43008 | C17: =$B$11 -> 0.27740973 | D17: =B17*C17 -> 11930.838 | E17: =D17/$B$4 -> 1.3619678
A18: Other hardware | B18: =Inputs!B21 -> 80000 | C18: =$B$11 -> 0.27740973 | D18: =B18*C18 -> 22192.779 | E18: =D18/$B$4 -> 2.5334222
A19: Total hardware | B19: =SUM(B15:B18) -> 532008 | D19: =SUM(D15:D18) -> 200936.87 | E19: =SUM(E15:E18) -> 22.937999
A21: Power
A22: GPU power | B22: =Inputs!B7*Inputs!B8/1000 -> 11.2 | C22: kW
A23: CPU power | B23: =Inputs!B12*Inputs!B14/1000 -> 0.7 | C23: kW
A24: DRAM power | B24: =Inputs!B19/1000 -> 0.6 | C24: kW
A25: Other power | B25: =Inputs!B22/1000 -> 1.5 | C25: kW
A26: IT power (node) | B26: =SUM(B22:B25) -> 14 | C26: kW
A27: PUE | B27: =Inputs!B25 -> 1.2
A28: Facility power (node) | B28: =B26*B27 -> 16.8 | C28: kW
A29: Electricity price | B29: =Inputs!B24 -> 0.08
A30: Power cost | B30: =B28*B29 -> 1.344 | C30: $/node-hr
A32: Human / team (allocated across the fleet)
A33: Team size | B33: =Inputs!B45 -> 80
A34: Fully-loaded cost / FTE | B34: =Inputs!B46 -> 750000
A35: Annual human cost | B35: =B33*B34 -> 60000000
A36: Fleet size (nodes) | B36: =Inputs!B43 -> 500
A37: Human cost | B37: =B35/(B36*$B$4) -> 13.69863 | C37: $/node-hr
A39: SUMMARY — $ / node-hour by category
A40: Category | B40: $ / node-hour | C40: % of total
A41: GPU | B41: =E15 -> 18.250914 | C41: =B41/$B$47 -> 0.48053218
A42: CPU | B42: =E16 -> 0.79169444 | C42: =B42/$B$47 -> 0.02084469
A43: DRAM | B43: =E17 -> 1.3619678 | C43: =B43/$B$47 -> 0.035859537
A44: Other hardware | B44: =E18 -> 2.5334222 | C44: =B44/$B$47 -> 0.066703009
A45: Electricity | B45: =B30 -> 1.344 | C45: =B45/$B$47 -> 0.03538646
...

Sheet Throughput
A1: INFERENCE THROUGHPUT — measured GB300 anchor (Blackwell Ultra), scaled for model size
A2: Aggregate tokens/sec across many concurrent requests (high batch), then derated. Green = from Inputs.
A3: Reference (measured) — GB300, DeepSeek-R1 (671B / 37B active), FP4, throughput-optimised
A4: Ref decode (output) / node | B4: =Inputs!B37 -> 46700 | C4: tok/s | D4: MLPerf v5.1 GB300 NVL72 (5,842 tok/s/GPU)
A5: Ref prefill (input) / node | B5: =Inputs!B38 -> 116800 | C5: tok/s | D5: ~2.5x decode; prefill compute-bound
A6: Reference active params | B6: 37 | C6: B | D6: Active params of the benchmark model (DeepSeek-R1)
A8: Scaling to the modelled system
A9: Hardware multiplier | B9: =Inputs!B39 -> 1 | C9: x | D9: Anchor already on B300/GB300 (=1.0)
A10: MTP speedup (decode only) | B10: =Inputs!B34 -> 1 | C10: x | D10: Multi-token prediction / speculative decode
A11: Serving-efficiency derate | B11: =Inputs!B40 -> 0.7 | C11: % | D11: Interactive latency SLAs vs offline peak
A12: Active-param scaling | B12: =B6/Inputs!B30 -> 0.75510204 | C12: x | D12: ~1/active-params; V4 sparse attn makes long-ctx sub-linear (upside)
A14: Effective per-node throughput (B300, production)
A15: Decode (output) / node | B15: =B4*B9*B10*B11*B12 -> 24684.286 | C15: tok/s | D15: ref x hw-mult x MTP x derate x param-scale
A16: Prefill (input) / node | B16: =B5*B9*B11*B12 -> 61737.143 | C16: tok/s | D16: ref x hw-mult x derate x param-scale (no MTP)
A17: Decode (output) / GPU | B17: =B15/Inputs!B7 -> 3085.5357 | C17: tok/s | D17: Per GPU
A18: Prefill (input) / GPU | B18: =B16/Inputs!B7 -> 7717.1429 | C18: tok/s | D18: Per GPU
A20: Life-average tokens per OWNED node-hour
A21: Fleet utilisation | B21: =Inputs!B42 -> 0.5 | C21: % | D21: Average served load vs effective peak
A22: Output tokens / owned node-hr | B22: =B15*3600*B21 -> 44431714 | C22: tok | D22: Decode rate x 3600 x utilisation
A23: Input tokens / owned node-hr | B23: =B16*3600*B21 -> 1.1112686e+08 | C23: tok | D23: Prefill rate x 3600 x utilisation

Sheet Cost Model
A1: COST MODEL — per token, per task, per developer, vs market price
A2: Green = links to Node Economics / Throughput. Edit assumptions on the Inputs tab.
A3: KEY OUTPUTS
A4: Infra cost / 1M OUTPUT tokens | B4: =B19 -> 0.85480899
A5: Infra cost / 1M INPUT tokens | B5: =C19 -> 0.34177722
A6: Infra cost / coding task | B6: =B26 -> 0.059821992
A7: Infra cost / developer-day | B7: =B30 -> 1.4955498
A8: Infra cost as % of API list price | B8: =B39 -> 0.047857594
A9: Implied gross margin vs API price | B9: =B40 -> 0.95214241
A11: COST PER 1,000,000 TOKENS, BY CATEGORY
A12: Category | B12: $ / 1M output | C12: $ / 1M input | D12: % of total
A13: GPU | B13: ='Node Economics'!B41/Throughput!B22*1000000 -> 0.41076322 | C13: ='Node Economics'!B41/Throughput!B23*1000000 -> 0.16423495 | D13: =B13/$B$19 -> 0.48053218
A14: CPU | B14: ='Node Economics'!B42/Throughput!B22*1000000 -> 0.017818229 | C14: ='Node Economics'!B42/Throughput!B23*1000000 -> 0.0071242404 | D14: =B14/$B$19 -> 0.02084469
A15: DRAM | B15: ='Node Economics'!B43/Throughput!B22*1000000 -> 0.030653055 | C15: ='Node Economics'!B43/Throughput!B23*1000000 -> 0.012255973 | D15: =B15/$B$19 -> 0.035859537
A16: Other hardware | B16: ='Node Economics'!B44/Throughput!B22*1000000 -> 0.057018331 | C16: ='Node Economics'!B44/Throughput!B23*1000000 -> 0.022797569 | D16: =B16/$B$19 -> 0.066703009
A17: Electricity | B17: ='Node Economics'!B45/Throughput!B22*1000000 -> 0.030248664 | C17: ='Node Economics'!B45/Throughput!B23*1000000 -> 0.012094286 | D17: =B17/$B$19 -> 0.03538646
A18: Human | B18: ='Node Economics'!B46/Throughput!B22*1000000 -> 0.30830749 | C18: ='Node Economics'!B46/Throughput!B23*1000000 -> 0.1232702 | D18: =B18/$B$19 -> 0.36067413
A19: TOTAL | B19: =SUM(B13:B18) -> 0.85480899 | C19: =SUM(C13:C18) -> 0.34177722 | D19: =SUM(D13:D18) -> 1
A21: COST PER CODING TASK
A22: Input tokens / task | B22: =Inputs!B48 -> 100000
A23: Output tokens / task | B23: =Inputs!B49 -> 30000
A24: Input cost / task | B24: =B22*$C$19/1000000 -> 0.034177722
A25: Output cost / task | B25: =B23*$B$19/1000000 -> 0.02564427
A26: Total infra cost / task | B26: =B24+B25 -> 0.059821992
A28: COST PER DEVELOPER
A29: Tasks / developer / day | B29: =Inputs!B50 -> 25
A30: Infra cost / developer-day | B30: =B26*B29 -> 1.4955498
A31: Infra cost / developer-month | B31: =B30*22 -> 32.902096 | C31: 22 working days
A33: VS MARKET API PRICE
A34: API input price | B34: =Inputs!B52 -> 5 | C34: $/M tok
A35: API output price | B35: =Inputs!B53 -> 25 | C35: $/M tok
A36: API price / task | B36: =B22*B34/1000000+B23*B35/1000000 -> 1.25
A37: Modeled infra cost / task | B37: =B26 -> 0.059821992
A39: Infra cost as % of API price | B39: =B37/B36 -> 0.047857594
A40: Implied gross margin | B40: =1-B39 -> 0.95214241
A42: OPTIONAL CONTEXT — TRAINING (excluded from the 5 infra buckets above)
A43: Training run cost (all-in) | B43: =Inputs!B55 -> 100000000
A44: Tokens served over life | B44: =Inputs!B56*1000000 -> 100000000 | C44: M tokens
A45: Training amortisation | B45: =B43/B44 -> 1 | C45: $/M tokens
A46: Note: compare to total serving cost / 1M output (B19). Training can rival or exceed marginal serving cost.
...

Sheet Sources
A1: SOURCES
A2: Figure | B2: Value used | C2: Source (date) | D2: URL
A3: Engineering basis (architecture) | B3: V4-Pro: 1.6T total / 49B active, FP4 MoE | C3: DeepSeek-V4-Pro model card / NVIDIA (Apr 2026) | D3: https://huggingface.co/deepseek-ai/DeepSeek-V4-Pro
A4: Hybrid sparse attention (CSA+HCA) | B4: ~90% KV-cache, ~73% FLOPs reduction vs V3.2 | C4: NVIDIA Technical Blog; LMSYS (Apr 2026) | D4: https://developer.nvidia.com/blog/build-with-deepseek-v4-using-nvidia-blackwell-and-gpu-accelerated-endpoints/
A5: V4 inference internals (MTP, mHC) | B5: SWA + C4/C128 compression, MTP spec-decode | C5: LMSYS / SGLang Day-0 (Apr 2026) | D5: https://www.lmsys.org/blog/2026-04-25-deepseek-v4/
A6: Frontier coding leaders | B6: Opus 4.8 / GPT-5.5 ~88.6% SWE-bench Verified | C6: Lushbinary; VentureBeat (Jun 2026) | D6: https://venturebeat.com/technology/anthropics-claude-opus-4-8-is-here-with-3x-cheaper-fast-mode-and-near-mythos-level-alignment
A7: B300 specs / price | B7: 288GB HBM3e, 1,400W, ~$40k-$50k; DGX ~$300k | C7: Spheron; VRLA Tech (2026) | D7: https://www.spheron.network/blog/nvidia-b300-blackwell-ultra-guide/
A8: GB300 measured throughput | B8: 5,842 tok/s/GPU on DeepSeek-R1 (offline) | C8: MLPerf Inference v5.1 via Barrack AI (2026) | D8: https://blog.barrack.ai/nvidia-rubin-vs-blackwell-rent-now-or-wait/
A9: GB300 serving (prefill:decode) | B9: V3.2: 7,360 prefill / 2,816 decode tok/s/GPU | C9: vLLM Blog GB300 (Feb 2026) | D9: https://blog.vllm.ai/2026/02/13/gb300-deepseek.html
A10: Electricity price | B10: US industrial ~$0.073/kWh; hyperscale <$0.05 | C10: Network Installers; EIA (2026) | D10: https://thenetworkinstallers.com/blog/data-center-energy-consumption-statistics/
A11: PUE | B11: Liquid-cooled AI DC ~1.1-1.2 | C11: Uptime Institute via above (2026) | D11: https://thenetworkinstallers.com/blog/data-center-energy-consumption-statistics/
A12: Server DRAM price | B12: Server DDR5 RDIMM ~$14/GB (64GB RDIMM >$900, Q1'26) | C12: rampricesusa; PCSP; TechPowerUp (2026) | D12: https://rampricesusa.com/
A13: Frontier engineering comp | B13: Senior TC ~$550k-$870k+ loaded | C13: JobsByCulture; Levels.fyi (2026) | D13: https://jobsbyculture.com/blog/ai-engineer-researcher-salary-2026
... A15: Open-weight price (for contrast) | B15: DeepSeek V4-Pro $0.435 in / $0.87 out per M | C15: morphllm (Jun 2026) | D15: https://www.morphllm.com/deepseek-v4
